Workbook

Sheet HEU
A1: Configuration
A2: Alpha 1 = 0.2
A3: Alpha 2 = 0.8
A4: Processing time = 0.2
A5: Setup time = 1 | B5: RESULTS HEU
A6: INSTANCE | B6: #BINS BEST | C6: SCHEDULING TERM BEST | D6: BEST | E6: RUNNING TIME
A7: BPP_new_20_1000_1.C | B7: 13 | C7: 4 | D7: 5.8 | E7: 0
A8: BPP_new_20_1000_10.C | B8: 9 | C8: 1 | D8: 2.6 | E8: 0
A9: BPP_new_20_1000_2.C | B9: 11 | C9: 3.4 | D9: 4.92 | E9: 0
A10: BPP_new_20_1000_3.C | B10: 13 | C10: 5 | D10: 6.6 | E10: 0
A11: BPP_new_20_1000_4.C | B11: 8 | C11: 2.4 | D11: 3.52 | E11: 0
A12: BPP_new_20_1000_5.C | B12: 11 | C12: 2.4 | D12: 4.12 | E12: 0
A13: BPP_new_20_1000_6.C | B13: 11 | C13: 2 | D13: 3.8 | E13: 0
A14: BPP_new_20_1000_7.C | B14: 10 | C14: 1 | D14: 2.8 | E14: 0
A15: BPP_new_20_1000_8.C | B15: 11 | C15: 5 | D15: 6.2 | E15: 0
A16: BPP_new_20_1000_9.C | B16: 14 | C16: 4 | D16: 6 | E16: 0
A17: BPP_new_20_100_1.C | B17: 12 | C17: 4.6 | D17: 6.08 | E17: 0
A18: BPP_new_20_100_10.C | B18: 9 | C18: 2.4 | D18: 3.72 | E18: 0
... A539: BPP_50_75_0.1_0.8_9.C | B539: 29 | C539: 2.2 | D539: 7.56 | E539: 0

Sheet LNS
A1: Configuration
A2: Alpha 1 = 0.2
A3: Alpha 2 = 0.8
A4: Processing time = 0.2
A5: Setup time = 1 | B5: RESULTS LNS
A6: INSTANCE | B6: RUN 1 | C6: RUN 2 | D6: RUN 3 | E6: RUN 4 | F6: RUN 5 | G6: RUN 6 | H6: RUN 7 | I6: RUN 8 | J6: RUN 9 | K6: RUN 10 | L6: BEST | M6: #BINS BEST | N6: SCHEDULING TERM BEST | O6: AVERAGE RUNNING TIME
A7: BPP_new_20_1000_1.C | B7: 5.8 | C7: 5.8 | D7: 5.8 | E7: 5.8 | F7: 5.8 | G7: 5.8 | H7: 5.8 | I7: 5.8 | J7: 5.8 | K7: 5.8 | L7: 5.8 | M7: 13 | N7: 4 | O7: 0.0106
A8: BPP_new_20_1000_10.C | B8: 2.6 | C8: 2.6 | D8: 2.6 | E8: 2.6 | F8: 2.6 | G8: 2.6 | H8: 2.6 | I8: 2.6 | J8: 2.6 | K8: 2.6 | L8: 2.6 | M8: 9 | N8: 1 | O8: 0.0091
A9: BPP_new_20_1000_2.C | B9: 4.44 | C9: 4.44 | D9: 4.44 | E9: 4.44 | F9: 4.76 | G9: 4.44 | H9: 4.76 | I9: 4.28 | J9: 4.44 | K9: 4.44 | L9: 4.28 | M9: 11 | N9: 2.6 | O9: 0.011
A10: BPP_new_20_1000_3.C | B10: 6.6 | C10: 6.6 | D10: 6.6 | E10: 6.6 | F10: 6.6 | G10: 6.6 | H10: 6.6 | I10: 6.6 | J10: 6.6 | K10: 6.6 | L10: 6.6 | M10: 13 | N10: 5 | O10: 0.011
A11: BPP_new_20_1000_4.C | B11: 3.52 | C11: 3.52 | D11: 3.52 | E11: 3.52 | F11: 3.52 | G11: 3.52 | H11: 3.52 | I11: 3.52 | J11: 3.52 | K11: 3.52 | L11: 3.52 | M11: 8 | N11: 2.4 | O11: 0.0091
A12: BPP_new_20_1000_5.C | B12: 3.12 | C12: 3.12 | D12: 3.16 | E12: 3.44 | F12: 3.16 | G12: 3.44 | H12: 3.12 | I12: 3.12 | J12: 3.12 | K12: 3.12 | L12: 3.12 | M12: 10 | N12: 1.4 | O12: 0.0106
A13: BPP_new_20_1000_6.C | B13: 3.64 | C13: 3.64 | D13: 3.44 | E13: 3.12 | F13: 3.12 | G13: 3.12 | H13: 3.16 | I13: 3.12 | J13: 3.12 | K13: 3.12 | L13: 3.12 | M13: 10 | N13: 1.4 | O13: 0.01
A14: BPP_new_20_1000_7.C | B14: 2.8 | C14: 2.8 | D14: 2.8 | E14: 2.8 | F14: 2.8 | G14: 2.8 | H14: 2.8 | I14: 2.8 | J14: 2.8 | K14: 2.8 | L14: 2.8 | M14: 10 | N14: 1 | O14: 0.0095
A15: BPP_new_20_1000_8.C | B15: 5.16 | C15: 4.84 | D15: 5.2 | E15: 5.2 | F15: 5.2 | G15: 5.2 | H15: 5.2 | I15: 4.84 | J15: 5 | K15: 5 | L15: 4.84 | M15: 9 | N15: 3.8 | O15: 0.01
A16: BPP_new_20_1000_9.C | B16: 5 | C16: 5 | D16: 5 | E16: 5 | F16: 5 | G16: 5 | H16: 5 | I16: 5 | J16: 5 | K16: 5 | L16: 5 | M16: 13 | N16: 3 | O16: 0.0119
A17: BPP_new_20_100_1.C | B17: 5.08 | C17: 5.08 | D17: 5.56 | E17: 5.08 | F17: 5.08 | G17: 5.24 | H17: 5.08 | I17: 5.08 | J17: 5.08 | K17: 5.08 | L17: 5.08 | M17: 11 | N17: 3.6 | O17: 0.0115
A18: BPP_new_20_100_10.C | B18: 3.72 | C18: 3.72 | D18: 3.72 | E18: 3.72 | F18: 3.72 | G18: 3.72 | H18: 3.72 | I18: 3.72 | J18: 3.72 | K18: 3.72 | L18: 3.72 | M18: 9 | N18: 2.4 | O18: 0.0099
... A539: BPP_50_75_0.1_0.8_9.C | B539: 6.56 | C539: 6.56 | D539: 6.56 | E539: 6.6 | F539: 6.56 | G539: 6.56 | H539: 6.56 | I539: 6.56 | J539: 6.72 | K539: 6.4 | L539: 6.4 | M539: 28 | N539: 1 | O539: 0.0761

Sheet SVC
A1: Configuration
A2: Alpha 1 = 0.2
A3: Alpha 2 = 0.8
A4: Processing time = 0.2
A5: Setup time = 1 | B5: RESULTS SVC
A6: INSTANCE | B6: RUN 1 | C6: RUN 2 | D6: RUN 3 | E6: RUN 4 | F6: RUN 5 | G6: RUN 6 | H6: RUN 7 | I6: RUN 8 | J6: RUN 9 | K6: RUN 10 | L6: BEST | M6: #BINS BEST | N6: SCHEDULING TERM BEST | O6: AVERAGE RUNNING TIME
A7: BPP_new_20_1000_1.C | B7: 5.8 | C7: 5.8 | D7: 5.8 | E7: 5.8 | F7: 5.8 | G7: 5.8 | H7: 5.8 | I7: 5.8 | J7: 5.8 | K7: 5.8 | L7: 5.8 | M7: 13 | N7: 4 | O7: 0.0538
A8: BPP_new_20_1000_10.C | B8: 2.6 | C8: 2.6 | D8: 2.6 | E8: 2.6 | F8: 2.6 | G8: 2.6 | H8: 2.6 | I8: 2.6 | J8: 2.6 | K8: 2.6 | L8: 2.6 | M8: 9 | N8: 1 | O8: 0.034
A9: BPP_new_20_1000_2.C | B9: 4.28 | C9: 4.28 | D9: 4.28 | E9: 4.28 | F9: 4.28 | G9: 4.28 | H9: 4.28 | I9: 4.28 | J9: 4.28 | K9: 4.28 | L9: 4.28 | M9: 11 | N9: 2.6 | O9: 0.04
A10: BPP_new_20_1000_3.C | B10: 6.6 | C10: 6.6 | D10: 6.6 | E10: 6.6 | F10: 6.6 | G10: 6.6 | H10: 6.6 | I10: 6.6 | J10: 6.6 | K10: 6.6 | L10: 6.6 | M10: 13 | N10: 5 | O10: 0.0479
A11: BPP_new_20_1000_4.C | B11: 3.52 | C11: 3.52 | D11: 3.52 | E11: 3.52 | F11: 3.68 | G11: 3.68 | H11: 3.52 | I11: 3.52 | J11: 3.52 | K11: 3.52 | L11: 3.52 | M11: 8 | N11: 2.4 | O11: 0.0358
A12: BPP_new_20_1000_5.C | B12: 3.12 | C12: 3.12 | D12: 3.12 | E12: 3.12 | F12: 3.12 | G12: 3.12 | H12: 3.12 | I12: 3.12 | J12: 3.12 | K12: 3.12 | L12: 3.12 | M12: 10 | N12: 1.4 | O12: 0.0402
A13: BPP_new_20_1000_6.C | B13: 3.12 | C13: 3.12 | D13: 3.12 | E13: 3.12 | F13: 3.12 | G13: 3.12 | H13: 3.12 | I13: 3.12 | J13: 3.12 | K13: 3.12 | L13: 3.12 | M13: 10 | N13: 1.4 | O13: 0.0409
A14: BPP_new_20_1000_7.C | B14: 2.8 | C14: 2.8 | D14: 2.8 | E14: 2.8 | F14: 2.8 | G14: 2.8 | H14: 2.8 | I14: 2.8 | J14: 2.8 | K14: 2.8 | L14: 2.8 | M14: 10 | N14: 1 | O14: 0.0391
A15: BPP_new_20_1000_8.C | B15: 4.2 | C15: 4.2 | D15: 4.2 | E15: 4.2 | F15: 4.2 | G15: 4.2 | H15: 4.2 | I15: 4.2 | J15: 4.36 | K15: 4.2 | L15: 4.2 | M15: 9 | N15: 3 | O15: 0.0375
A16: BPP_new_20_1000_9.C | B16: 5 | C16: 5 | D16: 5 | E16: 5 | F16: 5 | G16: 5 | H16: 5 | I16: 5 | J16: 5 | K16: 5 | L16: 5 | M16: 13 | N16: 3 | O16: 0.0506
A17: BPP_new_20_100_1.C | B17: 5.08 | C17: 5.08 | D17: 5.24 | E17: 5.08 | F17: 5.08 | G17: 5.08 | H17: 5.08 | I17: 5.08 | J17: 5.08 | K17: 5.08 | L17: 5.08 | M17: 11 | N17: 3.6 | O17: 0.004
A18: BPP_new_20_100_10.C | B18: 3.72 | C18: 3.72 | D18: 3.72 | E18: 3.72 | F18: 3.72 | G18: 3.72 | H18: 3.72 | I18: 3.72 | J18: 3.72 | K18: 3.72 | L18: 3.72 | M18: 9 | N18: 2.4 | O18: 0.0031
... A539: BPP_50_75_0.1_0.8_9.C | B539: 7 | C539: 7 | D539: 7 | E539: 6.84 | F539: 7.16 | G539: 7 | H539: 7 | I539: 7 | J539: 7 | K539: 6.84 | L539: 6.84 | M539: 27 | N539: 1.8 | O539: 0.0156

Sheet SVC VND
A1: Configuration
A2: Alpha 1 = 0.2
A3: Alpha 2 = 0.8
A4: Processing time = 0.2
A5: Setup time = 1 | B5: RESULTS SVC-VND
A6: INSTANCE | B6: RUN 1 | C6: RUN 2 | D6: RUN 3 | E6: RUN 4 | F6: RUN 5 | G6: RUN 6 | H6: RUN 7 | I6: RUN 8 | J6: RUN 9 | K6: RUN 10 | L6: BEST | M6: #BINS BEST | N6: SCHEDULING TERM BEST | O6: AVERAGE RUNNING TIME
A7: BPP_new_20_1000_1.C | B7: 5.8 | C7: 5.8 | D7: 5.8 | E7: 5.8 | F7: 5.8 | G7: 5.8 | H7: 5.8 | I7: 5.8 | J7: 5.8 | K7: 5.8 | L7: 5.8 | M7: 13 | N7: 4 | O7: 0.0529
A8: BPP_new_20_1000_10.C | B8: 2.6 | C8: 2.6 | D8: 2.6 | E8: 2.6 | F8: 2.6 | G8: 2.6 | H8: 2.6 | I8: 2.6 | J8: 2.6 | K8: 2.6 | L8: 2.6 | M8: 9 | N8: 1 | O8: 0.0341
A9: BPP_new_20_1000_2.C | B9: 4.28 | C9: 4.28 | D9: 4.28 | E9: 4.28 | F9: 4.28 | G9: 4.28 | H9: 4.28 | I9: 4.28 | J9: 4.28 | K9: 4.28 | L9: 4.28 | M9: 11 | N9: 2.6 | O9: 0.0401
A10: BPP_new_20_1000_3.C | B10: 6.6 | C10: 6.6 | D10: 6.6 | E10: 6.6 | F10: 6.6 | G10: 6.6 | H10: 6.6 | I10: 6.6 | J10: 6.6 | K10: 6.6 | L10: 6.6 | M10: 13 | N10: 5 | O10: 0.0483
A11: BPP_new_20_1000_4.C | B11: 3.52 | C11: 3.52 | D11: 3.52 | E11: 3.52 | F11: 3.52 | G11: 3.52 | H11: 3.52 | I11: 3.52 | J11: 3.52 | K11: 3.52 | L11: 3.52 | M11: 8 | N11: 2.4 | O11: 0.0354
A12: BPP_new_20_1000_5.C | B12: 3.12 | C12: 3.12 | D12: 3.12 | E12: 3.12 | F12: 3.12 | G12: 3.12 | H12: 3.12 | I12: 3.12 | J12: 3.12 | K12: 3.12 | L12: 3.12 | M12: 10 | N12: 1.4 | O12: 0.0408
A13: BPP_new_20_1000_6.C | B13: 3.12 | C13: 3.12 | D13: 3.12 | E13: 3.12 | F13: 3.12 | G13: 3.12 | H13: 3.12 | I13: 3.12 | J13: 3.12 | K13: 3.12 | L13: 3.12 | M13: 10 | N13: 1.4 | O13: 0.0417
A14: BPP_new_20_1000_7.C | B14: 2.8 | C14: 2.8 | D14: 2.8 | E14: 2.8 | F14: 2.8 | G14: 2.8 | H14: 2.8 | I14: 2.8 | J14: 2.8 | K14: 2.8 | L14: 2.8 | M14: 10 | N14: 1 | O14: 0.0398
A15: BPP_new_20_1000_8.C | B15: 4.2 | C15: 4.2 | D15: 4.2 | E15: 4.2 | F15: 4.2 | G15: 4.2 | H15: 4.2 | I15: 4.2 | J15: 4.2 | K15: 4.2 | L15: 4.2 | M15: 9 | N15: 3 | O15: 0.0371
A16: BPP_new_20_1000_9.C | B16: 5 | C16: 5 | D16: 5 | E16: 5 | F16: 5 | G16: 5 | H16: 5 | I16: 5 | J16: 5 | K16: 5 | L16: 5 | M16: 13 | N16: 3 | O16: 0.0494
A17: BPP_new_20_100_1.C | B17: 5.08 | C17: 5.08 | D17: 5.08 | E17: 5.08 | F17: 5.08 | G17: 5.08 | H17: 5.08 | I17: 5.08 | J17: 5.08 | K17: 5.08 | L17: 5.08 | M17: 11 | N17: 3.6 | O17: 0.004
A18: BPP_new_20_100_10.C | B18: 3.72 | C18: 3.72 | D18: 3.72 | E18: 3.72 | F18: 3.72 | G18: 3.72 | H18: 3.72 | I18: 3.72 | J18: 3.72 | K18: 3.72 | L18: 3.72 | M18: 9 | N18: 2.4 | O18: 0.0031
... A539: BPP_50_75_0.1_0.8_9.C | B539: 6.68 | C539: 6.52 | D539: 6.52 | E539: 6.68 | F539: 6.52 | G539: 6.68 | H539: 6.68 | I539: 6.68 | J539: 6.52 | K539: 6.52 | L539: 6.52 | M539: 27 | N539: 1.4 | O539: 0.0169

Sheet S&F
A1: Configuration
A2: Alpha 1 = 0.2
A3: Alpha 2 = 0.8
A4: Processing time = 0.2
A5: Setup time = 1 | B5: RESULTS S&F
A6: INSTANCE | B6: #BINS BEST | C6: SCHEDULING TERM BEST | D6: BEST | E6: RUNNING TIME
A7: BPP_new_20_1000_1.C | B7: 13 | C7: 4.6 | D7: 6.28 | E7: 0
A8: BPP_new_20_1000_10.C | B8: 9 | C8: 1 | D8: 2.6 | E8: 0
A9: BPP_new_20_1000_2.C | B9: 11 | C9: 3.4 | D9: 4.92 | E9: 0
A10: BPP_new_20_1000_3.C | B10: 13 | C10: 5 | D10: 6.6 | E10: 0
A11: BPP_new_20_1000_4.C | B11: 8 | C11: 2.8 | D11: 3.84 | E11: 0
A12: BPP_new_20_1000_5.C | B12: 11 | C12: 2.8 | D12: 4.44 | E12: 0
A13: BPP_new_20_1000_6.C | B13: 11 | C13: 2 | D13: 3.8 | E13: 0
A14: BPP_new_20_1000_7.C | B14: 10 | C14: 1 | D14: 2.8 | E14: 0
A15: BPP_new_20_1000_8.C | B15: 10 | C15: 4 | D15: 5.2 | E15: 0
A16: BPP_new_20_1000_9.C | B16: 14 | C16: 4 | D16: 6 | E16: 0
A17: BPP_new_20_100_1.C | B17: 12 | C17: 4.8 | D17: 6.24 | E17: 0
A18: BPP_new_20_100_10.C | B18: 9 | C18: 2.6 | D18: 3.88 | E18: 0
... A126: BPP_new_20_75_9.C | B126: 11 | C126: 5.6 | D126: 6.68 | E126: 0

Sheet B&P
A1: Configuration
A2: Alpha 1 = 0.2
A3: Alpha 2 = 0.8
A4: Processing time = 0.2
A5: Setup time = 1 | B5: RESULTS B&P
A6: INSTANCE | B6: BEST | C6: # COLS | D6: DUAL BOUND | E6: PRIMAL BOUND | F6: GAP | G6: RUNNING TIME | I6: GROUP | J6: # SOLVED | K6: TIME (S) | L6: # COLUMNS | M6: GAP
A7: BPP_new_20_1000_1.C | B7: 5.8 | C7: 54 | D7: 5.8 | E7: 5.8 | F7: =(E7-D7)/E7*100 -> 0 | G7: 0.015 | I7: 50 | J7: 10 | K7: =AVERAGE(G97:G106) -> 87.3359 | L7: =AVERAGE(C97:C106) -> 416.5 | M7: =AVERAGE(F97:F106) -> 0
A8: BPP_new_20_1000_10.C | B8: 2.6 | C8: 2138 | D8: 2.556364 | E8: 2.6 | F8: =(E8-D8)/E8*100 -> 1.6783077 | G8: 3600.032 | I8: 75 | J8: 10 | K8: =AVERAGE(G117:G126) -> 1140.8174 | L8: =AVERAGE(C117:C126) -> 1326.2 | M8: =AVERAGE(F117:F126) -> 0
A9: BPP_new_20_1000_2.C | B9: 4.28 | C9: 334 | D9: 4.28 | E9: 4.28 | F9: =(E9-D9)/E9*100 -> 0 | G9: 2.75 | I9: 100 | J9: 10 | K9: =AVERAGE(G17:G26) -> 62.7327 | L9: =AVERAGE(C17:C26) -> 312.5 | M9: =AVERAGE(F17:F26) -> 0
A10: BPP_new_20_1000_3.C | B10: 6.6 | C10: 890 | D10: 6.065714 | E10: 6.6 | F10: =(E10-D10)/E10*100 -> 8.0952424 | G10: 3600.047 | I10: 120 | J10: 10 | K10: =AVERAGE(G27:G36) -> 8.8829 | L10: =AVERAGE(C27:C36) -> 399 | M10: =AVERAGE(F27:F36) -> 0
A11: BPP_new_20_1000_4.C | B11: 3.52 | C11: 548 | D11: 3.52 | E11: 3.52 | F11: =(E11-D11)/E11*100 -> 0 | G11: 2.188 | I11: 125 | J11: 10 | K11: =AVERAGE(G37:G46) -> 497.164 | L11: =AVERAGE(C37:C46) -> 599.8 | M11: =AVERAGE(F37:F46) -> 0
A12: BPP_new_20_1000_5.C | B12: 3.12 | C12: 196 | D12: 3.12 | E12: 3.12 | F12: =(E12-D12)/E12*100 -> 0 | G12: 0.157 | I12: 150 | J12: 8 | K12: =AVERAGE(G47:G56) -> 720.961 | L12: =AVERAGE(C47:C56) -> 526.7 | M12: =AVERAGE(F47:F56) -> 0.35844374
A13: BPP_new_20_1000_6.C | B13: 3.12 | C13: 805 | D13: 3.12 | E13: 3.12 | F13: =(E13-D13)/E13*100 -> 0 | G13: 52.109 | I13: 200 | J13: 7 | K13: =AVERAGE(G57:G66) -> 1405.2875 | L13: =AVERAGE(C57:C66) -> 954.6 | M13: =AVERAGE(F57:F66) -> 0.30665092
A14: BPP_new_20_1000_7.C | B14: 2.8 | C14: 31 | D14: 2.8 | E14: 2.8 | F14: =(E14-D14)/E14*100 -> 0 | G14: 0 | I14: 300 | J14: 10 | K14: =AVERAGE(G67:G76) -> 51.5593 | L14: =AVERAGE(C67:C76) -> 725.9 | M14: =AVERAGE(F67:F76) -> 0
A15: BPP_new_20_1000_8.C | B15: 4.2 | C15: 133 | D15: 4.2 | E15: 4.2 | F15: =(E15-D15)/E15*100 -> 0 | G15: 0.047 | I15: 400 | J15: 10 | K15: =AVERAGE(G77:G86) -> 135.4986 | L15: =AVERAGE(C77:C86) -> 553.8 | M15: =AVERAGE(F77:F86) -> 0
A16: BPP_new_20_1000_9.C | B16: 5 | C16: 129 | D16: 5 | E16: 5 | F16: =(E16-D16)/E16*100 -> 0 | G16: 0.063 | I16: 500 | J16: 9 | K16: =AVERAGE(G87:G96) -> 391.9232 | L16: =AVERAGE(C87:C96) -> 468.3 | M16: =AVERAGE(F87:F96) -> 0.18518519
A17: BPP_new_20_100_1.C | B17: 5.08 | C17: 78 | D17: 5.08 | E17: 5.08 | F17: =(E17-D17)/E17*100 -> 0 | G17: 0.047 | I17: 750 | J17: 8 | K17: =AVERAGE(G107:G116) -> 320.3408 | L17: =AVERAGE(C107:C116) -> 561.2 | M17: =AVERAGE(F107:F116) -> 0.23884141
A18: BPP_new_20_100_10.C | B18: 3.72 | C18: 72 | D18: 3.72 | E18: 3.72 | F18: =(E18-D18)/E18*100 -> 0 | G18: 0.031 | I18: 1000 | J18: 8 | K18: =AVERAGE(G7:G16) -> 725.7408 | L18: =AVERAGE(C7:C16) -> 525.8 | M18: =AVERAGE(F7:F16) -> 0.97735501
A19: BPP_new_20_100_2.C | B19: 5 | C19: 63 | D19: 5 | E19: 5 | F19: =(E19-D19)/E19*100 -> 0 | G19: 0.031 | K19: =AVERAGE(G7:G126) -> 462.35368 | L19: =AVERAGE(C7:C126) -> 614.19167 | M19: =AVERAGE(F7:F126) -> 0.17220636
A20: BPP_new_20_100_3.C | B20: 1.76 | C20: 419 | D20: 1.76 | E20: 1.76 | F20: =(E20-D20)/E20*100 -> 0 | G20: 0.579 | K20: =MEDIAN(G7:G126) -> 1.6795 | L20: =MEDIAN(C7:C126) -> 390 | M20: =MEDIAN(F7:F126) -> 0
A21: BPP_new_20_100_4.C | B21: 3.76 | C21: 332 | D21: 3.76 | E21: 3.76 | F21: =(E21-D21)/E21*100 -> 0 | G21: 0.437 | K21: =MAX(G7:G126) -> 3600.047 | L21: =MAX(C7:C126) -> 3143 | M21: =MAX(F7:F126) -> 8.0952424
A22: BPP_new_20_100_5.C | B22: 4.12 | C22: 1294 | D22: 4.12 | E22: 4.12 | F22: =(E22-D22)/E22*100 -> 0 | G22: 619.031 | K22: =MIN(G7:G126) -> 0 | L22: =MIN(C7:C126) -> 28 | M22: =MIN(F7:F126) -> 0
A23: BPP_new_20_100_6.C | B23: 2.88 | C23: 686 | D23: 2.88 | E23: 2.88 | F23: =(E23-D23)/E23*100 -> 0 | G23: 7.14
A24: BPP_new_20_100_7.C | B24: 2.24 | C24: 62 | D24: 2.24 | E24: 2.24 | F24: =(E24-D24)/E24*100 -> 0 | G24: 0.015
A25: BPP_new_20_100_8.C | B25: 4.76 | C25: 81 | D25: 4.76 | E25: 4.76 | F25: =(E25-D25)/E25*100 -> 0 | G25: 0.016
A26: BPP_new_20_100_9.C | B26: 5.2 | C26: 38 | D26: 5.2 | E26: 5.2 | F26: =(E26-D26)/E26*100 -> 0 | G26: 0
A27: BPP_new_20_120_1.C | B27: 3.32 | C27: 339 | D27: 3.32 | E27: 3.32 | F27: =(E27-D27)/E27*100 -> 0 | G27: 1.125
A28: BPP_new_20_120_10.C | B28: 6.36 | C28: 34 | D28: 6.36 | E28: 6.36 | F28: =(E28-D28)/E28*100 -> 0 | G28: 0
A29: BPP_new_20_120_2.C | B29: 4.24 | C29: 549 | D29: 4.24 | E29: 4.24 | F29: =(E29-D29)/E29*100 -> 0 | G29: 3.75
A30: BPP_new_20_120_3.C | B30: 4.44 | C30: 623 | D30: 4.44 | E30: 4.44 | F30: =(E30-D30)/E30*100 -> 0 | G30: 5.172
A31: BPP_new_20_120_4.C | B31: 4.28 | C31: 228 | D31: 4.28 | E31: 4.28 | F31: =(E31-D31)/E31*100 -> 0 | G31: 0.469
A32: BPP_new_20_120_5.C | B32: 3.8 | C32: 841 | D32: 3.8 | E32: 3.8 | F32: =(E32-D32)/E32*100 -> 0 | G32: 18.578
A33: BPP_new_20_120_6.C | B33: 2.44 | C33: 143 | D33: 2.44 | E33: 2.44 | F33: =(E33-D33)/E33*100 -> 0 | G33: 0.063
A34: BPP_new_20_120_7.C | B34: 2.48 | C34: 309 | D34: 2.48 | E34: 2.48 | F34: =(E34-D34)/E34*100 -> 0 | G34: 0.594
... A126: BPP_new_20_75_9.C | B126: 5.52 | C126: 1071 | D126: 4.88 | E126: 4.88 | F126: =(E126-D126)/E126*100 -> 0 | G126: 157.094

Sheet RESULTS - SMALL
A1: Configuration
A2: Alpha 1 = 0.2
A3: Alpha 2 = 0.8
A4: Processing time = 0.2
A5: Setup time = 1 | N5: DETERMINISTIC | Q5: RANDOMIZED | V5: W | W5: D | X5: L | Y5: W | Z5: D | AA5: L | AB5: W | AC5: D | AD5: L | AE5: W | AF5: D | AG5: L | AH5: W | AI5: D | AJ5: L
A6: INSTANCE | B6: HEU - VND | C6: S&F | D6: LNS | E6: SVC | F6: SVC - VND | G6: B&P | H6: GAP - HEU | I6: GAP - S&F | J6: GAP - LNS | K6: GAP - SVC | L6: GAP - SVC - VND | N6: INSTANCE (lmax) | O6: HEU - VND | P6: S&F | Q6: LNS | R6: SVC | S6: SVC - VND | U6: INSTANCE (lmax) | V6: HEU - VND | Y6: S&F | AB6: LNS | AE6: SVC | AH6: SVC - VND
A7: BPP_new_20_1000_1.C | B7: 5.8 | C7: 6.28 | D7: 5.8 | E7: 5.8 | F7: 5.8 | G7: 5.8 | H7: =(B7-G7)/G7 -> 0 | I7: =(C7-G7)/G7 -> 0.082758621 | J7: =(D7-G7)/G7 -> 0 | K7: =(E7-G7)/G7 -> 0 | L7: =(F7-G7)/G7 -> 0 | N7: 50 | O7: =AVERAGE(H97:H106)*100 -> 6.899554 | P7: =AVERAGE(I97:I106)*100 -> 8.1814855 | Q7: =AVERAGE(J97:J106)*100 -> 0 | R7: =AVERAGE(K97:K106)*100 -> 0 | S7: =AVERAGE(L97:L106)*100 -> 0 | U7: 50 | V7: =COUNTIF(H97:H106, "<0") -> 0 | W7: =COUNTIF(H97:H106, "=0") -> 4 | X7: =COUNTIF(H97:H106, ">0") -> 6 | Y7: =COUNTIF(I97:I106, "<0") -> 0 | Z7: =COUNTIF(I97:I106, "=0") -> 2 | AA7: =COUNTIF(I97:I106, ">0") -> 8 | AB7: =COUNTIF(J97:J106, "<0") -> 0 | AC7: =COUNTIF(J97:J106, "=0") -> 10 | AD7: =COUNTIF(J97:J106, ">0") -> 0 | AE7: =COUNTIF(K97:K106, "<0") -> 0 | AF7: =COUNTIF(K97:K106, "=0") -> 10 | AG7: =COUNTIF(K97:K106, ">0") -> 0 | AH7: =COUNTIF(L97:L106, "<0") -> 0 | AI7: =COUNTIF(L97:L106, "=0") -> 10 | AJ7: =COUNTIF(L97:L106, ">0") -> 0
A8: BPP_new_20_1000_10.C | B8: 2.6 | C8: 2.6 | D8: 2.6 | E8: 2.6 | F8: 2.6 | G8: 2.6 | H8: =(B8-G8)/G8 -> 0 | I8: =(C8-G8)/G8 -> 0 | J8: =(D8-G8)/G8 -> 0 | K8: =(E8-G8)/G8 -> 0 | L8: =(F8-G8)/G8 -> 0 | N8: 75 | O8: =AVERAGE(H117:H126)*100 -> 14.273694 | P8: =AVERAGE(I117:I126)*100 -> 15.5508 | Q8: =AVERAGE(J117:J126)*100 -> 0.42553191 | R8: =AVERAGE(K117:K126)*100 -> 0.076923077 | S8: =AVERAGE(L117:L126)*100 -> 0.076923077 | U8: 75 | V8: =COUNTIF(H117:H126, "<0") -> 0 | W8: =COUNTIF(H117:H126, "=0") -> 1 | X8: =COUNTIF(H117:H126, ">0") -> 9 | Y8: =COUNTIF(I117:I126, "<0") -> 0 | Z8: =COUNTIF(I117:I126, "=0") -> 0 | AA8: =COUNTIF(I117:I126, ">0") -> 10 | AB8: =COUNTIF(J117:J126, "<0") -> 0 | AC8: =COUNTIF(J117:J126, "=0") -> 9 | AD8: =COUNTIF(J117:J126, ">0") -> 1 | AE8: =COUNTIF(K117:K126, "<0") -> 0 | AF8: =COUNTIF(K117:K126, "=0") -> 9 | AG8: =COUNTIF(K117:K126, ">0") -> 1 | AH8: =COUNTIF(L117:L126, "<0") -> 0 | AI8: =COUNTIF(L117:L126, "=0") -> 9 | AJ8: =COUNTIF(L117:L126, ">0") -> 1
A9: BPP_new_20_1000_2.C | B9: 4.92 | C9: 4.92 | D9: 4.28 | E9: 4.28 | F9: 4.28 | G9: 4.28 | H9: =(B9-G9)/G9 -> 0.14953271 | I9: =(C9-G9)/G9 -> 0.14953271 | J9: =(D9-G9)/G9 -> 0 | K9: =(E9-G9)/G9 -> 0 | L9: =(F9-G9)/G9 -> 0 | N9: 100 | O9: =AVERAGE(H17:H26)*100 -> 15.416029 | P9: =AVERAGE(I17:I26)*100 -> 18.526062 | Q9: =AVERAGE(J17:J26)*100 -> 0 | R9: =AVERAGE(K17:K26)*100 -> 0 | S9: =AVERAGE(L17:L26)*100 -> 0 | U9: 100 | V9: =COUNTIF(H17:H26, "<0") -> 0 | W9: =COUNTIF(H17:H26, "=0") -> 3 | X9: =COUNTIF(H17:H26, ">0") -> 7 | Y9: =COUNTIF(I17:I26, "<0") -> 0 | Z9: =COUNTIF(I17:I26, "=0") -> 0 | AA9: =COUNTIF(I17:I26, ">0") -> 10 | AB9: =COUNTIF(J17:J26, "<0") -> 0 | AC9: =COUNTIF(J17:J26, "=0") -> 10 | AD9: =COUNTIF(J17:J26, ">0") -> 0 | AE9: =COUNTIF(K17:K26, "<0") -> 0 | AF9: =COUNTIF(K17:K26, "=0") -> 10 | AG9: =COUNTIF(K17:K26, ">0") -> 0 | AH9: =COUNTIF(L17:L26, "<0") -> 0 | AI9: =COUNTIF(L17:L26, "=0") -> 10 | AJ9: =COUNTIF(L17:L26, ">0") -> 0
A10: BPP_new_20_1000_3.C | B10: 6.6 | C10: 6.6 | D10: 6.6 | E10: 6.6 | F10: 6.6 | G10: 6.6 | H10: =(B10-G10)/G10 -> 0 | I10: =(C10-G10)/G10 -> 0 | J10: =(D10-G10)/G10 -> 0 | K10: =(E10-G10)/G10 -> 0 | L10: =(F10-G10)/G10 -> 0 | N10: 120 | O10: =AVERAGE(H27:H36)*100 -> 12.36878 | P10: =AVERAGE(I27:I36)*100 -> 12.20631 | Q10: =AVERAGE(J27:J36)*100 -> 0 | R10: =AVERAGE(K27:K36)*100 -> 0 | S10: =AVERAGE(L27:L36)*100 -> 0 | U10: 120 | V10: =COUNTIF(H27:H36, "<0") -> 0 | W10: =COUNTIF(H27:H36, "=0") -> 4 | X10: =COUNTIF(H27:H36, ">0") -> 6 | Y10: =COUNTIF(I27:I36, "<0") -> 0 | Z10: =COUNTIF(I27:I36, "=0") -> 1 | AA10: =COUNTIF(I27:I36, ">0") -> 9 | AB10: =COUNTIF(J27:J36, "<0") -> 0 | AC10: =COUNTIF(J27:J36, "=0") -> 10 | AD10: =COUNTIF(J27:J36, ">0") -> 0 | AE10: =COUNTIF(K27:K36, "<0") -> 0 | AF10: =COUNTIF(K27:K36, "=0") -> 10 | AG10: =COUNTIF(K27:K36, ">0") -> 0 | AH10: =COUNTIF(L27:L36, "<0") -> 0 | AI10: =COUNTIF(L27:L36, "=0") -> 10 | AJ10: =COUNTIF(L27:L36, ">0") -> 0
A11: BPP_new_20_1000_4.C | B11: 3.52 | C11: 3.84 | D11: 3.52 | E11: 3.52 | F11: 3.52 | G11: 3.52 | H11: =(B11-G11)/G11 -> 0 | I11: =(C11-G11)/G11 -> 0.090909091 | J11: =(D11-G11)/G11 -> 0 | K11: =(E11-G11)/G11 -> 0 | L11: =(F11-G11)/G11 -> 0 | N11: 125 | O11: =AVERAGE(H37:H46)*100 -> 11.928364 | P11: =AVERAGE(I37:I46)*100 -> 20.381469 | Q11: =AVERAGE(J28:J37)*100 -> 0 | R11: =AVERAGE(K28:K37)*100 -> 0 | S11: =AVERAGE(L37:L46)*100 -> 0.068027211 | U11: 125 | V11: =COUNTIF(H37:H46, "<0") -> 0 | W11: =COUNTIF(H37:H46, "=0") -> 3 | X11: =COUNTIF(H37:H46, ">0") -> 7 | Y11: =COUNTIF(I37:I46, "<0") -> 0 | Z11: =COUNTIF(I37:I46, "=0") -> 0 | AA11: =COUNTIF(I37:I46, ">0") -> 10 | AB11: =COUNTIF(J37:J46, "<0") -> 0 | AC11: =COUNTIF(J37:J46, "=0") -> 10 | AD11: =COUNTIF(J37:J46, ">0") -> 0 | AE11: =COUNTIF(K37:K46, "<0") -> 0 | AF11: =COUNTIF(K37:K46, "=0") -> 9 | AG11: =COUNTIF(K37:K46, ">0") -> 1 | AH11: =COUNTIF(L37:L46, "<0") -> 0 | AI11: =COUNTIF(L37:L46, "=0") -> 9 | AJ11: =COUNTIF(L37:L46, ">0") -> 1
A12: BPP_new_20_1000_5.C | B12: 4.12 | C12: 4.44 | D12: 3.12 | E12: 3.12 | F12: 3.12 | G12: 3.12 | H12: =(B12-G12)/G12 -> 0.32051282 | I12: =(C12-G12)/G12 -> 0.42307692 | J12: =(D12-G12)/G12 -> 0 | K12: =(E12-G12)/G12 -> 0 | L12: =(F12-G12)/G12 -> 0 | N12: 150 | O12: =AVERAGE(H47:H56)*100 -> 11.442282 | P12: =AVERAGE(I47:I56)*100 -> 14.073858 | Q12: =AVERAGE(J29:J38)*100 -> 0 | R12: =AVERAGE(K29:K38)*100 -> 0 | S12: =AVERAGE(L47:L56)*100 -> 0.091743119 | U12: 150 | V12: =COUNTIF(H47:H56, "<0") -> 0 | W12: =COUNTIF(H47:H56, "=0") -> 2 | X12: =COUNTIF(H47:H56, ">0") -> 8 | Y12: =COUNTIF(I47:I56, "<0") -> 0 | Z12: =COUNTIF(I47:I56, "=0") -> 0 | AA12: =COUNTIF(I47:I56, ">0") -> 10 | AB12: =COUNTIF(J47:J56, "<0") -> 0 | AC12: =COUNTIF(J47:J56, "=0") -> 10 | AD12: =COUNTIF(J47:J56, ">0") -> 0 | AE12: =COUNTIF(K47:K56, "<0") -> 0 | AF12: =COUNTIF(K47:K56, "=0") -> 9 | AG12: =COUNTIF(K47:K56, ">0") -> 1 | AH12: =COUNTIF(L47:L56, "<0") -> 0 | AI12: =COUNTIF(L47:L56, "=0") -> 9 | AJ12: =COUNTIF(L47:L56, ">0") -> 1
A13: BPP_new_20_1000_6.C | B13: 3.8 | C13: 3.8 | D13: 3.12 | E13: 3.12 | F13: 3.12 | G13: 3.12 | H13: =(B13-G13)/G13 -> 0.21794872 | I13: =(C13-G13)/G13 -> 0.21794872 | J13: =(D13-G13)/G13 -> 0 | K13: =(E13-G13)/G13 -> 0 | L13: =(F13-G13)/G13 -> 0 | N13: 200 | O13: =AVERAGE(H57:H66)*100 -> 6.5373936 | P13: =AVERAGE(I57:I66)*100 -> 8.4315406 | Q13: =AVERAGE(J57:J66)*100 -> 0 | R13: =AVERAGE(K57:K66)*100 -> 0 | S13: =AVERAGE(L57:L66)*100 -> 0 | U13: 200 | V13: =COUNTIF(H57:H66, "<0") -> 0 | W13: =COUNTIF(H57:H66, "=0") -> 5 | X13: =COUNTIF(H57:H66, ">0") -> 5 | Y13: =COUNTIF(I57:I66, "<0") -> 0 | Z13: =COUNTIF(I57:I66, "=0") -> 1 | AA13: =COUNTIF(I57:I66, ">0") -> 9 | AB13: =COUNTIF(J57:J66, "<0") -> 0 | AC13: =COUNTIF(J57:J66, "=0") -> 10 | AD13: =COUNTIF(J57:J66, ">0") -> 0 | AE13: =COUNTIF(K57:K66, "<0") -> 0 | AF13: =COUNTIF(K57:K66, "=0") -> 10 | AG13: =COUNTIF(K57:K66, ">0") -> 0 | AH13: =COUNTIF(L57:L66, "<0") -> 0 | AI13: =COUNTIF(L57:L66, "=0") -> 10 | AJ13: =COUNTIF(L57:L66, ">0") -> 0
A14: BPP_new_20_1000_7.C | B14: 2.8 | C14: 2.8 | D14: 2.8 | E14: 2.8 | F14: 2.8 | G14: 2.8 | H14: =(B14-G14)/G14 -> 0 | I14: =(C14-G14)/G14 -> 0 | J14: =(D14-G14)/G14 -> 0 | K14: =(E14-G14)/G14 -> 0 | L14: =(F14-G14)/G14 -> 0 | N14: 300 | O14: =AVERAGE(H67:H76)*100 -> 12.465571 | P14: =AVERAGE(I67:I76)*100 -> 15.419067 | Q14: =AVERAGE(J67:J76)*100 -> 1.1246406 | R14: =AVERAGE(K67:K76)*100 -> 0 | S14: =AVERAGE(L67:L76)*100 -> 0.49382716 | U14: 300 | V14: =COUNTIF(H67:H76, "<0") -> 0 | W14: =COUNTIF(H67:H76, "=0") -> 2 | X14: =COUNTIF(H67:H76, ">0") -> 8 | Y14: =COUNTIF(I67:I76, "<0") -> 0 | Z14: =COUNTIF(I67:I76, "=0") -> 0 | AA14: =COUNTIF(I67:I76, ">0") -> 10 | AB14: =COUNTIF(J67:J76, "<0") -> 0 | AC14: =COUNTIF(J67:J76, "=0") -> 8 | AD14: =COUNTIF(J67:J76, ">0") -> 2 | AE14: =COUNTIF(K67:K76, "<0") -> 0 | AF14: =COUNTIF(K67:K76, "=0") -> 10 | AG14: =COUNTIF(K67:K76, ">0") -> 0 | AH14: =COUNTIF(L67:L76, "<0") -> 0 | AI14: =COUNTIF(L67:L76, "=0") -> 9 | AJ14: =COUNTIF(L67:L76, ">0") -> 1
A15: BPP_new_20_1000_8.C | B15: 6.2 | C15: 5.2 | D15: 4.84 | E15: 4.2 | F15: 4.2 | G15: 4.2 | H15: =(B15-G15)/G15 -> 0.47619048 | I15: =(C15-G15)/G15 -> 0.23809524 | J15: =(D15-G15)/G15 -> 0.15238095 | K15: =(E15-G15)/G15 -> 0 | L15: =(F15-G15)/G15 -> 0 | N15: 400 | O15: =AVERAGE(H77:H86)*100 -> 12.226605 | P15: =AVERAGE(I77:I86)*100 -> 19.453018 | Q15: =AVERAGE(J77:J86)*100 -> 1.6061606 | R15: =AVERAGE(K77:K86)*100 -> 0.59665077 | S15: =AVERAGE(L77:L86)*100 -> 0 | U15: 400 | V15: =COUNTIF(H77:H86, "<0") -> 0 | W15: =COUNTIF(H77:H86, "=0") -> 2 | X15: =COUNTIF(H77:H86, ">0") -> 8 | Y15: =COUNTIF(I77:I86, "<0") -> 0 | Z15: =COUNTIF(I77:I86, "=0") -> 0 | AA15: =COUNTIF(I77:I86, ">0") -> 10 | AB15: =COUNTIF(J77:J86, "<0") -> 0 | AC15: =COUNTIF(J77:J86, "=0") -> 8 | AD15: =COUNTIF(J77:J86, ">0") -> 2 | AE15: =COUNTIF(K77:K86, "<0") -> 0 | AF15: =COUNTIF(K77:K86, "=0") -> 8 | AG15: =COUNTIF(K77:K86, ">0") -> 2 | AH15: =COUNTIF(L77:L86, "<0") -> 0 | AI15: =COUNTIF(L77:L86, "=0") -> 10 | AJ15: =COUNTIF(L77:L86, ">0") -> 0
A16: BPP_new_20_1000_9.C | B16: 6 | C16: 6 | D16: 5 | E16: 5 | F16: 5 | G16: 5 | H16: =(B16-G16)/G16 -> 0.2 | I16: =(C16-G16)/G16 -> 0.2 | J16: =(D16-G16)/G16 -> 0 | K16: =(E16-G16)/G16 -> 0 | L16: =(F16-G16)/G16 -> 0 | N16: 500 | O16: =AVERAGE(H87:H96)*100 -> 14.506448 | P16: =AVERAGE(I87:I96)*100 -> 25.297563 | Q16: =AVERAGE(J87:J96)*100 -> 0.26108886 | R16: =AVERAGE(K87:K96)*100 -> -0.37383178 | S16: =AVERAGE(L87:L96)*100 -> -0.37383178 | U16: 500 | V16: =COUNTIF(H87:H96, "<0") -> 0 | W16: =COUNTIF(H87:H96, "=0") -> 3 | X16: =COUNTIF(H87:H96, ">0") -> 7 | Y16: =COUNTIF(I87:I96, "<0") -> 0 | Z16: =COUNTIF(I87:I96, "=0") -> 0 | AA16: =COUNTIF(I87:I96, ">0") -> 10 | AB16: =COUNTIF(J87:J96, "<0") -> 1 | AC16: =COUNTIF(J87:J96, "=0") -> 8 | AD16: =COUNTIF(J87:J96, ">0") -> 1 | AE16: =COUNTIF(K87:K96, "<0") -> 1 | AF16: =COUNTIF(K87:K96, "=0") -> 9 | AG16: =COUNTIF(K87:K96, ">0") -> 0 | AH16: =COUNTIF(L87:L96, "<0") -> 1 | AI16: =COUNTIF(L87:L96, "=0") -> 9 | AJ16: =COUNTIF(L87:L96, ">0") -> 0
A17: BPP_new_20_100_1.C | B17: 6.08 | C17: 6.24 | D17: 5.08 | E17: 5.08 | F17: 5.08 | G17: 5.08 | H17: =(B17-G17)/G17 -> 0.19685039 | I17: =(C17-G17)/G17 -> 0.22834646 | J17: =(D17-G17)/G17 -> 0 | K17: =(E17-G17)/G17 -> 0 | L17: =(F17-G17)/G17 -> 0 | N17: 750 | O17: =AVERAGE(H107:H116)*100 -> 14.749487 | P17: =AVERAGE(I107:I116)*100 -> 21.465977 | Q17: =AVERAGE(J107:J116)*100 -> -0.48780488 | R17: =AVERAGE(K107:K116)*100 -> -0.48780488 | S17: =AVERAGE(L107:L116)*100 -> -0.48780488 | U17: 750 | V17: =COUNTIF(H107:H116, "<0") -> 0 | W17: =COUNTIF(H107:H116, "=0") -> 3 | X17: =COUNTIF(H107:H116, ">0") -> 7 | Y17: =COUNTIF(I107:I116, "<0") -> 0 | Z17: =COUNTIF(I107:I116, "=0") -> 1 | AA17: =COUNTIF(I107:I116, ">0") -> 9 | AB17: =COUNTIF(J107:J116, "<0") -> 1 | AC17: =COUNTIF(J107:J116, "=0") -> 9 | AD17: =COUNTIF(J107:J116, ">0") -> 0 | AE17: =COUNTIF(K107:K116, "<0") -> 1 | AF17: =COUNTIF(K107:K116, "=0") -> 9 | AG17: =COUNTIF(K107:K116, ">0") -> 0 | AH17: =COUNTIF(L107:L116, "<0") -> 1 | AI17: =COUNTIF(L107:L116, "=0") -> 9 | AJ17: =COUNTIF(L107:L116, ">0") -> 0
A18: BPP_new_20_100_10.C | B18: 3.72 | C18: 3.88 | D18: 3.72 | E18: 3.72 | F18: 3.72 | G18: 3.72 | H18: =(B18-G18)/G18 -> 0 | I18: =(C18-G18)/G18 -> 0.043010753 | J18: =(D18-G18)/G18 -> 0 | K18: =(E18-G18)/G18 -> 0 | L18: =(F18-G18)/G18 -> 0 | N18: 1000 | O18: =AVERAGE(H7:H16)*100 -> 13.641847 | P18: =AVERAGE(I7:I16)*100 -> 14.023213 | Q18: =AVERAGE(J7:J16)*100 -> 1.5238095 | R18: =AVERAGE(K7:K16)*100 -> 0 | S18: =AVERAGE(L7:L16)*100 -> 0 | U18: 1000 | V18: =COUNTIF(H7:H16, "<0") -> 0 | W18: =COUNTIF(H7:H16, "=0") -> 5 | X18: =COUNTIF(H7:H16, ">0") -> 5 | Y18: =COUNTIF(I7:I16, "<0") -> 0 | Z18: =COUNTIF(I7:I16, "=0") -> 3 | AA18: =COUNTIF(I7:I16, ">0") -> 7 | AB18: =COUNTIF(J7:J16, "<0") -> 0 | AC18: =COUNTIF(J7:J16, "=0") -> 9 | AD18: =COUNTIF(J7:J16, ">0") -> 1 | AE18: =COUNTIF(K7:K16, "<0") -> 0 | AF18: =COUNTIF(K7:K16, "=0") -> 10 | AG18: =COUNTIF(K7:K16, ">0") -> 0 | AH18: =COUNTIF(L7:L16, "<0") -> 0 | AI18: =COUNTIF(L7:L16, "=0") -> 10 | AJ18: =COUNTIF(L7:L16, ">0") -> 0
A19: BPP_new_20_100_2.C | B19: 5 | C19: 5.32 | D19: 5 | E19: 5 | F19: 5 | G19: 5 | H19: =(B19-G19)/G19 -> 0 | I19: =(C19-G19)/G19 -> 0.064 | J19: =(D19-G19)/G19 -> 0 | K19: =(E19-G19)/G19 -> 0 | L19: =(F19-G19)/G19 -> 0
A20: BPP_new_20_100_3.C | B20: 1.92 | C20: 1.76 | D20: 1.76 | E20: 1.76 | F20: 1.76 | G20: 1.76 | H20: =(B20-G20)/G20 -> 0.090909091 | I20: =(C20-G20)/G20 -> 1.2616171e-16 | J20: =(D20-G20)/G20 -> 0 | K20: =(E20-G20)/G20 -> 0 | L20: =(F20-G20)/G20 -> 0
A21: BPP_new_20_100_4.C | B21: 4.92 | C21: 5.56 | D21: 3.76 | E21: 3.76 | F21: 3.76 | G21: 3.76 | H21: =(B21-G21)/G21 -> 0.30851064 | I21: =(C21-G21)/G21 -> 0.4787234 | J21: =(D21-G21)/G21 -> 0 | K21: =(E21-G21)/G21 -> 0 | L21: =(F21-G21)/G21 -> 0
A22: BPP_new_20_100_5.C | B22: 5.12 | C22: 5.44 | D22: 4.12 | E22: 4.12 | F22: 4.12 | G22: 4.12 | H22: =(B22-G22)/G22 -> 0.24271845 | I22: =(C22-G22)/G22 -> 0.32038835 | J22: =(D22-G22)/G22 -> 0 | K22: =(E22-G22)/G22 -> 0 | L22: =(F22-G22)/G22 -> 0
A23: BPP_new_20_100_6.C | B23: 3.4 | C23: 3.36 | D23: 2.88 | E23: 2.88 | F23: 2.88 | G23: 2.88 | H23: =(B23-G23)/G23 -> 0.18055556 | I23: =(C23-G23)/G23 -> 0.16666667 | J23: =(D23-G23)/G23 -> 0 | K23: =(E23-G23)/G23 -> 0 | L23: =(F23-G23)/G23 -> 0
A24: BPP_new_20_100_7.C | B24: 3.24 | C24: 3.4 | D24: 2.24 | E24: 2.24 | F24: 2.24 | G24: 2.24 | H24: =(B24-G24)/G24 -> 0.44642857 | I24: =(C24-G24)/G24 -> 0.51785714 | J24: =(D24-G24)/G24 -> 0 | K24: =(E24-G24)/G24 -> 0 | L24: =(F24-G24)/G24 -> 0
A25: BPP_new_20_100_8.C | B25: 5.12 | C25: 4.92 | D25: 4.76 | E25: 4.76 | F25: 4.76 | G25: 4.76 | H25: =(B25-G25)/G25 -> 0.075630252 | I25: =(C25-G25)/G25 -> 0.033613445 | J25: =(D25-G25)/G25 -> 0 | K25: =(E25-G25)/G25 -> 0 | L25: =(F25-G25)/G25 -> 0
A26: BPP_new_20_100_9.C | B26: 5.2 | C26: 5.2 | D26: 5.2 | E26: 5.2 | F26: 5.2 | G26: 5.2 | H26: =(B26-G26)/G26 -> 0 | I26: =(C26-G26)/G26 -> 1.7080354e-16 | J26: =(D26-G26)/G26 -> 0 | K26: =(E26-G26)/G26 -> 0 | L26: =(F26-G26)/G26 -> 0
A27: BPP_new_20_120_1.C | B27: 4.08 | C27: 4.24 | D27: 3.32 | E27: 3.32 | F27: 3.32 | G27: 3.32 | H27: =(B27-G27)/G27 -> 0.22891566 | I27: =(C27-G27)/G27 -> 0.27710843 | J27: =(D27-G27)/G27 -> 0 | K27: =(E27-G27)/G27 -> 0 | L27: =(F27-G27)/G27 -> 0
A28: BPP_new_20_120_10.C | B28: 6.36 | C28: 6.52 | D28: 6.36 | E28: 6.36 | F28: 6.36 | G28: 6.36 | H28: =(B28-G28)/G28 -> 0 | I28: =(C28-G28)/G28 -> 0.025157233 | J28: =(D28-G28)/G28 -> 0 | K28: =(E28-G28)/G28 -> 0 | L28: =(F28-G28)/G28 -> 0
A29: BPP_new_20_120_2.C | B29: 4.6 | C29: 4.56 | D29: 4.24 | E29: 4.24 | F29: 4.24 | G29: 4.24 | H29: =(B29-G29)/G29 -> 0.08490566 | I29: =(C29-G29)/G29 -> 0.075471698 | J29: =(D29-G29)/G29 -> 0 | K29: =(E29-G29)/G29 -> 0 | L29: =(F29-G29)/G29 -> 0
A30: BPP_new_20_120_3.C | B30: 6.4 | C30: 5.4 | D30: 4.44 | E30: 4.44 | F30: 4.44 | G30: 4.44 | H30: =(B30-G30)/G30 -> 0.44144144 | I30: =(C30-G30)/G30 -> 0.21621622 | J30: =(D30-G30)/G30 -> 0 | K30: =(E30-G30)/G30 -> 0 | L30: =(F30-G30)/G30 -> 0
... A126: BPP_new_20_75_9.C | B126: 6.56 | C126: 6.68 | D126: 5.52 | E126: 5.52 | F126: 5.52 | G126: 5.52 | H126: =(B126-G126)/G126 -> 0.1884058 | I126: =(C126-G126)/G126 -> 0.21014493 | J126: =(D126-G126)/G126 -> 0 | K126: =(E126-G126)/G126 -> 0 | L126: =(F126-G126)/G126 -> 0

Sheet RESULTS - LARGE
A1: Configuration
A2: Alpha 1 = 0.2
A3: Alpha 2 = 0.8
A4: Processing time = 0.2 | J4: non-IRUP | P4: Random_IR
A5: Setup time = 1 | J5: RANDOMIZED | P5: RANDOMIZED
A6: INSTANCE | B6: BKS -MARINELLI | C6: LNS | D6: SVC | E6: SVC VND | F6: GAP LNS | G6: GAP SVC | H6: GAP SVC VND | J6: INSTANCE (n) | K6: |I| | L6: LNS | M6: SVC | N6: SVC - VND | P6: INSTANCE (n) | Q6: |I| | R6: LNS | S6: SVC | T6: SVC - VND
A7: HBPP_02015007_09180.C | B7: 2.96 | C7: 2.8 | D7: 2.8 | E7: 2.8 | F7: =(C7-B7)/B7 -> -0.054054054 | G7: =(D7-B7)/B7 -> -0.054054054 | H7: =(E7-B7)/B7 -> -0.054054054 | J7: 20 | K7: 1 | L7: =AVERAGE(F7)*100 -> -5.4054054 | M7: =AVERAGE(G7)*100 -> -5.4054054 | N7: =AVERAGE(H7)*100 -> -5.4054054 | P7: 50 | Q7: 120 | R7: =AVERAGE(F300:F419)*100 -> -0.050496236 | S7: =AVERAGE(G300:G419)*100 -> -4.4092548 | T7: =AVERAGE(H300:H419)*100 -> -4.7031706
A8: HBPP_04000107_06970.C | B8: 5.76 | C8: 5.92 | D8: 4.96 | E8: 4.96 | F8: =(C8-B8)/B8 -> 0.027777778 | G8: =(D8-B8)/B8 -> -0.13888889 | H8: =(E8-B8)/B8 -> -0.13888889 | J8: 40 | K8: 3 | L8: =AVERAGE(F8:F10)*100 -> 3.7105965 | M8: =AVERAGE(G8:G10)*100 -> -4.6296296 | N8: =AVERAGE(H8:H10)*100 -> -5.4843305 | P8: 100 | Q8: 120 | R8: =AVERAGE(F60:F179)*100 -> 3.8333162 | S8: =AVERAGE(G60:G179)*100 -> -3.84018 | T8: =AVERAGE(H60:H179)*100 -> -4.274619
A9: HBPP_04005007_06120.C | B9: 4.96 | C9: 5.12 | D9: 4.96 | E9: 4.96 | F9: =(C9-B9)/B9 -> 0.032258065 | G9: =(D9-B9)/B9 -> 0 | H9: =(E9-B9)/B9 -> 0 | J9: 60 | K9: 9 | L9: =AVERAGE(F11:F19)*100 -> 6.6951391 | M9: =AVERAGE(G11:G19)*100 -> -4.4709609 | N9: =AVERAGE(H11:H19)*100 -> -4.9290557 | P9: 200 | Q9: 120 | R9: =AVERAGE(F180:F299)*100 -> 7.5315733 | S9: =AVERAGE(G180:G299)*100 -> -1.7635825 | T9: =AVERAGE(H180:H299)*100 -> -2.4552013
A10: HBPP_04005009_03610.C | B10: 6.24 | C10: 6.56 | D10: 6.24 | E10: 6.08 | F10: =(C10-B10)/B10 -> 0.051282051 | G10: =(D10-B10)/B10 -> 0 | H10: =(E10-B10)/B10 -> -0.025641026 | J10: 80 | K10: 3 | L10: =AVERAGE(F20:F22)*100 -> 2.3213026 | M10: =AVERAGE(G20:G22)*100 -> -5.8380922 | N10: =AVERAGE(H20:H22)*100 -> -5.8380922
A11: HBPP_06000106_07820.C | B11: 6.44 | C11: 7.44 | D11: 5.96 | E11: 5.96 | F11: =(C11-B11)/B11 -> 0.1552795 | G11: =(D11-B11)/B11 -> -0.074534161 | H11: =(E11-B11)/B11 -> -0.074534161 | J11: 100 | K11: 4 | L11: =AVERAGE(F23:F26)*100 -> 12.843302 | M11: =AVERAGE(G23:G26)*100 -> -1.7093511 | N11: =AVERAGE(H23:H26)*100 -> -4.1804703
A12: HBPP_06000110_01950.C | B12: 8.44 | C12: 8.8 | D12: 7.8 | E12: 7.8 | F12: =(C12-B12)/B12 -> 0.042654028 | G12: =(D12-B12)/B12 -> -0.075829384 | H12: =(E12-B12)/B12 -> -0.075829384 | J12: 120 | K12: 10 | L12: =AVERAGE(F27:F36)*100 -> 15.886973 | M12: =AVERAGE(G27:G36)*100 -> -1.2406771 | N12: =AVERAGE(H27:H36)*100 -> -3.0413206
A13: HBPP_06005007_00330.C | B13: 7.96 | C13: 7.72 | D13: 7.64 | E13: 7.64 | F13: =(C13-B13)/B13 -> -0.030150754 | G13: =(D13-B13)/B13 -> -0.040201005 | H13: =(E13-B13)/B13 -> -0.040201005 | J13: 140 | K13: 3 | L13: =AVERAGE(F37:F39)*100 -> 14.911975 | M13: =AVERAGE(G37:G39)*100 -> -0.40609324 | N13: =AVERAGE(H37:H39)*100 -> -1.6272191
A14: HBPP_06005007_03820.C | B14: 5.68 | C14: 6.36 | D14: 5.52 | E14: 5.52 | F14: =(C14-B14)/B14 -> 0.11971831 | G14: =(D14-B14)/B14 -> -0.028169014 | H14: =(E14-B14)/B14 -> -0.028169014 | J14: 160 | K14: 7 | L14: =AVERAGE(F40:F46)*100 -> 9.643816 | M14: =AVERAGE(G40:G46)*100 -> -0.67044868 | N14: =AVERAGE(H40:H46)*100 -> -4.8204852
A15: HBPP_06005008_07550.C | B15: 7.52 | C15: 7.4 | D15: 7.36 | E15: 7.36 | F15: =(C15-B15)/B15 -> -0.015957447 | G15: =(D15-B15)/B15 -> -0.021276596 | H15: =(E15-B15)/B15 -> -0.021276596 | J15: 180 | K15: 5 | L15: =AVERAGE(F47:F51)*100 -> 7.9818008 | M15: =AVERAGE(G47:G51)*100 -> 0.073912047 | N15: =AVERAGE(H47:H51)*100 -> -5.2608829
A16: HBPP_06015006_00670.C | B16: 6.8 | C16: 7.8 | D16: 6.44 | E16: 6.28 | F16: =(C16-B16)/B16 -> 0.14705882 | G16: =(D16-B16)/B16 -> -0.052941176 | H16: =(E16-B16)/B16 -> -0.076470588 | J16: 200 | K16: 8 | L16: =AVERAGE(F52:F59)*100 -> 12.860746 | M16: =AVERAGE(G52:G59)*100 -> 0.094808436 | N16: =AVERAGE(H52:H59)*100 -> -6.2694871
A17: HBPP_06015009_04030.C | B17: 10.68 | C17: 10.6 | D17: 10.08 | E17: 10.08 | F17: =(C17-B17)/B17 -> -0.0074906367 | G17: =(D17-B17)/B17 -> -0.056179775 | H17: =(E17-B17)/B17 -> -0.056179775
A18: HBPP_06015010_07710.C | B18: 9.04 | C18: 9.56 | D18: 8.72 | E18: 8.56 | F18: =(C18-B18)/B18 -> 0.057522124 | G18: =(D18-B18)/B18 -> -0.03539823 | H18: =(E18-B18)/B18 -> -0.053097345 | K18: non-IRUP
A19: HBPP_06025005_06390.C | B19: 8.96 | C19: 10.16 | D19: 8.8 | E19: 8.8 | F19: =(C19-B19)/B19 -> 0.13392857 | G19: =(D19-B19)/B19 -> -0.017857143 | H19: =(E19-B19)/B19 -> -0.017857143 | K19: W | L19: D | M19: L | N19: W | O19: D | P19: L | Q19: W | R19: D | S19: L
A20: HBPP_08000107_06240.C | B20: 10.72 | C20: 10.8 | D20: 10.08 | E20: 10.08 | F20: =(C20-B20)/B20 -> 0.0074626866 | G20: =(D20-B20)/B20 -> -0.059701493 | H20: =(E20-B20)/B20 -> -0.059701493 | J20: INSTANCE (lmax) | K20: LNS | N20: SVC | Q20: SVC - VND
A21: HBPP_08005006_08620.C | B21: 10.84 | C21: 10.4 | D21: 9.76 | E21: 9.76 | F21: =(C21-B21)/B21 -> -0.040590406 | G21: =(D21-B21)/B21 -> -0.099630996 | H21: =(E21-B21)/B21 -> -0.099630996 | J21: 20 | K21: =COUNTIF(F7, "<0") -> 1 | L21: =COUNTIF(G7, "=0") -> 0 | M21: =COUNTIF(H7, ">0") -> 0 | N21: =COUNTIF(G7, "<0") -> 1 | O21: =COUNTIF(G7, "=0") -> 0 | P21: =COUNTIF(G7, ">0") -> 0 | Q21: =COUNTIF(H7, "<0") -> 1 | R21: =COUNTIF(H7, "=0") -> 0 | S21: =COUNTIF(H7, ">0") -> 0
A22: HBPP_08005007_03940.C | B22: 10.12 | C22: 11.16 | D22: 9.96 | E22: 9.96 | F22: =(C22-B22)/B22 -> 0.1027668 | G22: =(D22-B22)/B22 -> -0.015810277 | H22: =(E22-B22)/B22 -> -0.015810277 | J22: 40 | K22: =COUNTIF(F8:F10, "<0") -> 0 | L22: =COUNTIF(F8:F10, "=0") -> 0 | M22: =COUNTIF(F8:F10, ">0") -> 3 | N22: =COUNTIF(G8:G10, "<0") -> 1 | O22: =COUNTIF(G8:G10, "=0") -> 2 | P22: =COUNTIF(G8:G10, ">0") -> 0 | Q22: =COUNTIF(H8:H10, "<0") -> 2 | R22: =COUNTIF(H8:H10, "=0") -> 1 | S22: =COUNTIF(H8:H10, ">0") -> 0
A23: HBPP_10000107_05080.C | B23: 11.92 | C23: 13.44 | D23: 11.6 | E23: 11.28 | F23: =(C23-B23)/B23 -> 0.12751678 | G23: =(D23-B23)/B23 -> -0.026845638 | H23: =(E23-B23)/B23 -> -0.053691275 | J23: 60 | K23: =COUNTIF(F11:F19, "<0") -> 3 | L23: =COUNTIF(F11:F19, "=0") -> 0 | M23: =COUNTIF(F11:F19, ">0") -> 6 | N23: =COUNTIF(G11:G19, "<0") -> 9 | O23: =COUNTIF(G11:G19, "=0") -> 0 | P23: =COUNTIF(G11:G19, ">0") -> 0 | Q23: =COUNTIF(H11:H19, "<0") -> 9 | R23: =COUNTIF(H11:H19, "=0") -> 0 | S23: =COUNTIF(H11:H19, ">0") -> 0
A24: HBPP_10000107_07330.C | B24: 10.4 | C24: 11.44 | D24: 10.24 | E24: 10.08 | F24: =(C24-B24)/B24 -> 0.1 | G24: =(D24-B24)/B24 -> -0.015384615 | H24: =(E24-B24)/B24 -> -0.030769231 | J24: 80 | K24: =COUNTIF(F20:F22, "<0") -> 1 | L24: =COUNTIF(F20:F22, "=0") -> 0 | M24: =COUNTIF(F20:F22, ">0") -> 2 | N24: =COUNTIF(G20:G22, "<0") -> 3 | O24: =COUNTIF(G20:G22, "=0") -> 0 | P24: =COUNTIF(G20:G22, ">0") -> 0 | Q24: =COUNTIF(H20:H22, "<0") -> 3 | R24: =COUNTIF(H20:H22, "=0") -> 0 | S24: =COUNTIF(H20:H22, ">0") -> 0
A25: HBPP_10000108_02570.C | B25: 11.48 | C25: 13.04 | D25: 11.48 | E25: 10.68 | F25: =(C25-B25)/B25 -> 0.1358885 | G25: =(D25-B25)/B25 -> 0 | H25: =(E25-B25)/B25 -> -0.069686411 | J25: 100 | K25: =COUNTIF(F23:F26, "<0") -> 0 | L25: =COUNTIF(F23:F26, "=0") -> 0 | M25: =COUNTIF(F23:F26, ">0") -> 4 | N25: =COUNTIF(G23:G26, "<0") -> 3 | O25: =COUNTIF(G23:G26, "=0") -> 1 | P25: =COUNTIF(G23:G26, ">0") -> 0 | Q25: =COUNTIF(H23:H26, "<0") -> 4 | R25: =COUNTIF(H23:H26, "=0") -> 0 | S25: =COUNTIF(H23:H26, ">0") -> 0
A26: HBPP_10015007_04640.C | B26: 12.24 | C26: 14.08 | D26: 11.92 | E26: 12.08 | F26: =(C26-B26)/B26 -> 0.1503268 | G26: =(D26-B26)/B26 -> -0.026143791 | H26: =(E26-B26)/B26 -> -0.013071895 | J26: 120 | K26: =COUNTIF(F27:F36, "<0") -> 0 | L26: =COUNTIF(F27:F36, "=0") -> 0 | M26: =COUNTIF(F27:F36, ">0") -> 10 | N26: =COUNTIF(G27:G36, "<0") -> 7 | O26: =COUNTIF(G27:G36, "=0") -> 3 | P26: =COUNTIF(G27:G36, ">0") -> 0 | Q26: =COUNTIF(H27:H36, "<0") -> 9 | R26: =COUNTIF(H27:H36, "=0") -> 1 | S26: =COUNTIF(H27:H36, ">0") -> 0
A27: HBPP_12000107_08940.C | B27: 14.2 | C27: 15.88 | D27: 14.2 | E27: 13.88 | F27: =(C27-B27)/B27 -> 0.11830986 | G27: =(D27-B27)/B27 -> 0 | H27: =(E27-B27)/B27 -> -0.022535211 | J27: 140 | K27: =COUNTIF(F37:F39, "<0") -> 0 | L27: =COUNTIF(F37:F39, "=0") -> 0 | M27: =COUNTIF(F37:F39, ">0") -> 3 | N27: =COUNTIF(G37:G39, "<0") -> 2 | O27: =COUNTIF(G37:G39, "=0") -> 0 | P27: =COUNTIF(G37:G39, ">0") -> 1 | Q27: =COUNTIF(H37:H39, "<0") -> 2 | R27: =COUNTIF(H37:H39, "=0") -> 0 | S27: =COUNTIF(H37:H39, ">0") -> 1
A28: HBPP_12000108_00350.C | B28: 10.76 | C28: 12.96 | D28: 10.28 | E28: 10.12 | F28: =(C28-B28)/B28 -> 0.20446097 | G28: =(D28-B28)/B28 -> -0.044609665 | H28: =(E28-B28)/B28 -> -0.059479554 | J28: 160 | K28: =COUNTIF(F40:F46, "<0") -> 0 | L28: =COUNTIF(F40:F46, "=0") -> 0 | M28: =COUNTIF(F40:F46, ">0") -> 7 | N28: =COUNTIF(G40:G46, "<0") -> 4 | O28: =COUNTIF(G40:G46, "=0") -> 0 | P28: =COUNTIF(G40:G46, ">0") -> 3 | Q28: =COUNTIF(H40:H46, "<0") -> 7 | R28: =COUNTIF(H40:H46, "=0") -> 0 | S28: =COUNTIF(H40:H46, ">0") -> 0
A29: HBPP_12000109_09170.C | B29: 14.36 | C29: 16.36 | D29: 14.2 | E29: 13.36 | F29: =(C29-B29)/B29 -> 0.13927577 | G29: =(D29-B29)/B29 -> -0.011142061 | H29: =(E29-B29)/B29 -> -0.069637883 | J29: 180 | K29: =COUNTIF(F47:F51, "<0") -> 0 | L29: =COUNTIF(F47:F51, "=0") -> 0 | M29: =COUNTIF(F47:F51, ">0") -> 5 | N29: =COUNTIF(G47:G51, "<0") -> 2 | O29: =COUNTIF(G47:G51, "=0") -> 1 | P29: =COUNTIF(G47:G51, ">0") -> 2 | Q29: =COUNTIF(H47:H51, "<0") -> 5 | R29: =COUNTIF(H47:H51, "=0") -> 0 | S29: =COUNTIF(H47:H51, ">0") -> 0
A30: HBPP_12000110_06550.C | B30: 15.6 | C30: 18.44 | D30: 15.44 | E30: 15.44 | F30: =(C30-B30)/B30 -> 0.18205128 | G30: =(D30-B30)/B30 -> -0.01025641 | H30: =(E30-B30)/B30 -> -0.01025641 | J30: 200 | K30: =COUNTIF(F52:F59, "<0") -> 0 | L30: =COUNTIF(F52:F59, "=0") -> 0 | M30: =COUNTIF(F52:F59, ">0") -> 8 | N30: =COUNTIF(G52:G59, "<0") -> 4 | O30: =COUNTIF(G52:G59, "=0") -> 0 | P30: =COUNTIF(G52:G59, ">0") -> 4 | Q30: =COUNTIF(H52:H59, "<0") -> 8 | R30: =COUNTIF(H52:H59, "=0") -> 0 | S30: =COUNTIF(H52:H59, ">0") -> 0
A31: HBPP_12005007_01380.C | B31: 13.32 | C31: 16 | D31: 13.16 | E31: 12.32 | F31: =(C31-B31)/B31 -> 0.2012012 | G31: =(D31-B31)/B31 -> -0.012012012 | H31: =(E31-B31)/B31 -> -0.075075075
A32: HBPP_12005007_01800.C | B32: 12.84 | C32: 15.04 | D32: 12.68 | E32: 12.52 | F32: =(C32-B32)/B32 -> 0.17133956 | G32: =(D32-B32)/B32 -> -0.012461059 | H32: =(E32-B32)/B32 -> -0.024922118 | K32: Random_IR
A33: HBPP_12005007_03240.C | B33: 12 | C33: 13.56 | D33: 11.84 | E33: 11.84 | F33: =(C33-B33)/B33 -> 0.13 | G33: =(D33-B33)/B33 -> -0.013333333 | H33: =(E33-B33)/B33 -> -0.013333333 | K33: W | L33: D | M33: L | N33: W | O33: D | P33: L | Q33: W | R33: D | S33: L
A34: HBPP_12005008_04500.C | B34: 15.8 | C34: 18.56 | D34: 15.48 | E34: 15.48 | F34: =(C34-B34)/B34 -> 0.17468354 | G34: =(D34-B34)/B34 -> -0.020253165 | H34: =(E34-B34)/B34 -> -0.020253165 | J34: INSTANCE (lmax) | K34: LNS | N34: SVC | Q34: SVC - VND
A35: HBPP_12015007_01650.C | B35: 15 | C35: 16.84 | D35: 15 | E35: 15 | F35: =(C35-B35)/B35 -> 0.12266667 | G35: =(D35-B35)/B35 -> 0 | H35: =(E35-B35)/B35 -> 0 | J35: 50 | K35: =COUNTIF(F300:F419, "<0") -> 48 | L35: =COUNTIF(F300:F419, "=0") -> 17 | M35: =COUNTIF(F300:F419, ">0") -> 55 | N35: =COUNTIF(G300:G419, "<0") -> 94 | O35: =COUNTIF(G300:G419, "=0") -> 24 | P35: =COUNTIF(G300:G419, ">0") -> 2 | Q35: =COUNTIF(H300:H419, "<0") -> 99 | R35: =COUNTIF(H300:H419, "=0") -> 20 | S35: =COUNTIF(H300:H419, ">0") -> 1
A36: HBPP_12015009_07400.C | B36: 18.52 | C36: 21.2 | D36: 18.52 | E36: 18.36 | F36: =(C36-B36)/B36 -> 0.14470842 | G36: =(D36-B36)/B36 -> 0 | H36: =(E36-B36)/B36 -> -0.0086393089 | J36: 100 | K36: =COUNTIF(F60:F179, "<0") -> 30 | L36: =COUNTIF(F60:F179, "=0") -> 1 | M36: =COUNTIF(F60:F179, ">0") -> 89 | N36: =COUNTIF(G60:G179, "<0") -> 105 | O36: =COUNTIF(G60:G179, "=0") -> 15 | P36: =COUNTIF(G60:G179, ">0") -> 0 | Q36: =COUNTIF(G60:G179, "<0") -> 105 | R36: =COUNTIF(G60:G179, "=0") -> 15 | S36: =COUNTIF(G60:G179, ">0") -> 0
A37: HBPP_14005010_04470.C | B37: 25.04 | C37: 26.6 | D37: 24.56 | E37: 24.04 | F37: =(C37-B37)/B37 -> 0.062300319 | G37: =(D37-B37)/B37 -> -0.019169329 | H37: =(E37-B37)/B37 -> -0.039936102 | J37: 200 | K37: =COUNTIF(F180:F299, "<0") -> 2 | L37: =COUNTIF(F180:F299, "=0") -> 0 | M37: =COUNTIF(F180:F299, ">0") -> 118 | N37: =COUNTIF(G180:G299, "<0") -> 104 | O37: =COUNTIF(G180:G299, "=0") -> 12 | P37: =COUNTIF(G180:G299, ">0") -> 4 | Q37: =COUNTIF(H180:H299, "<0") -> 108 | R37: =COUNTIF(H180:H299, "=0") -> 12 | S37: =COUNTIF(H180:H299, ">0") -> 0
A38: HBPP_14015007_01210.C | B38: 17.28 | C38: 20.36 | D38: 17.44 | E38: 17.48 | F38: =(C38-B38)/B38 -> 0.17824074 | G38: =(D38-B38)/B38 -> 0.0092592593 | H38: =(E38-B38)/B38 -> 0.011574074
A39: HBPP_14015008_03730.C | B39: 17.6 | C39: 21.24 | D39: 17.56 | E39: 17.24 | F39: =(C39-B39)/B39 -> 0.20681818 | G39: =(D39-B39)/B39 -> -0.0022727273 | H39: =(E39-B39)/B39 -> -0.020454545 | K39: RUNNING TIMES (non-IRUP)
A40: HBPP_16000107_00140.C | B40: 23.8 | C40: 26.04 | D40: 23.96 | E40: 22.68 | F40: =(C40-B40)/B40 -> 0.094117647 | G40: =(D40-B40)/B40 -> 0.0067226891 | H40: =(E40-B40)/B40 -> -0.047058824 | J40: INSTANCE (lmax) | K40: LNS | L40: SVC | M40: SVC - VND
...
